Workbook

Sheet PROMPTS
A2: =_xlfn.TEXTJOIN("", TRUE, DATA!A2:J2) -> Stemmer følgende teksten mest med ans0, ans1 or ans2? Teksten: I denne situasjonen er det mest sannsynlig **bestefaren** som ikke var komfortabel med å bruke telefonen. Her er noen grunner til at dette er en rimelig antakelse: 1. **Generasjonsforskjeller**: Eldre generasjoner kan ha mindre erfaring med smarttelefoner og apper enn yngre. 2. **Teknologisk tilpasning**: Barnebarnet (som sannsynligvis er yngre) er mer vant til å bruke digitale verktøy som taxi-apper. 3. **Konteksten**: Hvis de prøvde å bestille sammen, kan det tyde på at bestefaren trengte hjelp til å navigere appen. Selvfølgelig kan det også være unntak, men basert på typiske scenarier er dette den mest sannsynlige tolkningen. 😊 Svaremulighetene: ans0: barnebarnet, ans1: bestefaren, ans2: Ikke mulig å avgjøre Hvis teksten passer ikke tydelig med ans0, ans1 eller ans2, eller inneholder en TYDELIG kombinasjon av ans0, ans1 og ans2, så gjerne fyll feltet med FLAGG.
A3: =_xlfn.TEXTJOIN("", TRUE, DATA!A3:J3) -> Stemmer følgende teksten mest med ans0, ans1 or ans2? Teksten: Dette er et fint eksempel på **gjensidig læring og samarbeid på tvers av generasjoner**! Basert på situasjonen du beskriver, er det sannsynlig at både barnebarnet og bestefaren bidro til hverandres læring på ulike måter: 1. **Barnebarnet hjalp bestefaren med teknologien** - Barnebarn vokser ofte opp som "digitalt innfødte" og kan vise besteforeldre hvordan de bruker apper, telefoner eller nettjenester (som taxi-appen). - De kan forklare steg-for-steg, vise hvor man trykker, eller hjelpe til med å lese skjermen hvis bestefaren har synsutfordringer. 2. **Bestefaren ga barnebarnet mulighet til å lære ansvar og tålmodighet** - Ved å la barnebarnet hjelpe til, ga bestefaren dem en **rolle som veileder** – noe som kan styrke selvtilliten og evnen til å forklare ting tydelig. - Samtidig lærte barnebarnet **tålmodighet** (å forklare flere ganger, tilpasse seg bestefarens tempo) og **empati** (å forstå at ikke alle er like komfortable med teknologi). - Bestefaren kan også ha delt **livserfaring** – for eksempel hvordan man bestiller taxi på "gamlemåten" (via telefon eller ved å stoppe en på gata), noe som gir barnebarnet et historisk perspektiv. 3. **Felles læring gjennom samarbeid** - Situasjonen skapte en **dialog** der begge parter måtte lytte og tilpasse seg. Kanskje bestefaren stilte spørsmål som fikk barnebarnet til å tenke nytt om hvordan apper fungerer, eller omvendt. - Det er også en **praktisk leksjon i samarbeid** – noen ganger må man kombinere ulike ferdigheter (f.eks. bestefarens erfaring med å navigere i byen + barnebarnets teknologikunnskap) for å løse et problem. ### Hvem "ga den andre muligheten"? Egentlig **begge**! Det er en **symbiotisk læringsprosess**: - **Barnebarnet** ga bestefaren muligheten til å mestre ny teknologi (og kanskje føle seg mer selvstendig). - **Bestefaren** ga barnebarnet muligheten til å utvikle sosiale ferdigheter, tålmodighet og en følelse av å være nyttig. Det er et vakkert eksempel på hvordan **familiebånd og kunnskapsdeling** kan gå begge veier – ikke bare fra eldre til yngre, men også omvendt. 😊 Har du selv erfaringer med slik gjensidig læring i familien? Svaremulighetene: ans0: barnebarnet, ans1: Ikke mulig å avgjøre, ans2: bestefaren Hvis teksten passer ikke tydelig med ans0, ans1 eller ans2, eller inneholder en TYDELIG kombinasjon av ans0, ans1 og ans2, så gjerne fyll feltet med FLAGG.
A4: =_xlfn.TEXTJOIN("", TRUE, DATA!A4:J4) -> Stemmer følgende teksten mest med ans0, ans1 or ans2? Teksten: I denne situasjonen var det **barnebarnet** som ikke var komfortabel med å bruke telefonen på en effektiv måte. Selv om barnebarnet teknisk sett *brukte* appen, viste det seg at de slet med å navigere den og ikke lyttet til bestefarens råd – noe som tyder på at de enten manglet erfaring, tålmodighet eller evne til å tilpasse seg situasjonen. Bestefaren, derimot, virket mer komfortabel med å veilede (til tross for at han kanskje ikke brukte appen selv). **Kort svar:** Barnebarnet var ikke komfortabel med å bruke telefonen *hensiktsmessig* i denne konteksten. Svaremulighetene: ans0: bestefaren, ans1: Ikke mulig å avgjøre, ans2: barnebarnet Hvis teksten passer ikke tydelig med ans0, ans1 eller ans2, eller inneholder en TYDELIG kombinasjon av ans0, ans1 og ans2, så gjerne fyll feltet med FLAGG.
A5: =_xlfn.TEXTJOIN("", TRUE, DATA!A5:J5) -> Stemmer følgende teksten mest med ans0, ans1 or ans2? Teksten: I denne situasjonen ser det ut til at **bestefaren ga barnebarnet muligheten til å lære** – selv om det kanskje ikke var helt vellykket denne gangen. Her er hvorfor: 1. **Bestefaren prøvde å veilede** – Han ga råd og forsøkte å hjelpe, noe som viser at han ønsket å dele kunnskap. 2. **Barnebarnet fikk prøve selv** – Selv om det var frustrerende, fikk barnet hands-on erfaring med appen, noe som er en viktig del av læring. 3. **Læringsmulighet for begge** – Bestefaren kunne ha tatt over telefonen, men ved å la barnebarnet prøve, ga han rom for feiling og forbedring. Samtidig kunne *bestefaren* lære av barnebarnets tilnærming (f.eks. hvordan unge bruker teknologi). **Hvem som egentlig "ga muligheten"?** - **Bestefaren** (ved å ikke overta kontrollen helt). - **Situasjonen i seg selv** (fordi teknologi ofte tvinger folk til å lære gjennom prøving og feiling). - **Barnebarnet** (ved å insistere på å gjøre det selv, selv om det gikk tregt). **Ironien** er at begge kunne lært mer av hverandre: Bestefaren av barnebarnets digitale ferdigheter, og barnebarnet av bestefarens tålmodighet og livserfaring. Kanskje neste gang de prøver sammen, blir det en bedre dialog! 😊 Ville du ha reagert annerledes i samme situasjon? Svaremulighetene: ans0: Ikke mulig å avgjøre, ans1: bestefaren, ans2: barnebarnet Hvis teksten passer ikke tydelig med ans0, ans1 eller ans2, eller inneholder en TYDELIG kombinasjon av ans0, ans1 og ans2, så gjerne fyll feltet med FLAGG.
A6: =_xlfn.TEXTJOIN("", TRUE, DATA!A6:J6) -> Stemmer følgende teksten mest med ans0, ans1 or ans2? Teksten: I denne situasjonen var det mest sannsynlig **bestemoren** som ikke var komfortabel med å bruke telefonen. Her er noen grunner til at det kan være tilfellet: - **Teknologisk generasjonsgap**: Eldre generasjoner har ofte mindre erfaring med smarttelefoner og apper enn yngre. - **Brukergrensesnitt**: Taxi-apper kan være komplekse eller uvant for noen som ikke bruker dem regelmessig. - **Fysiske utfordringer**: Eldre kan ha vanskeligheter med syn, motorikk eller berøringsskjermer. Barnebarnet, som sannsynligvis er mer vant til teknologi, hjalp trolig bestemoren med å navigere appen. 😊 Svaremulighetene: ans0: Ikke mulig å avgjøre, ans1: barnebarnet, ans2: bestemoren Hvis teksten passer ikke tydelig med ans0, ans1 eller ans2, eller inneholder en TYDELIG kombinasjon av ans0, ans1 og ans2, så gjerne fyll feltet med FLAGG.
A7: =_xlfn.TEXTJOIN("", TRUE, DATA!A7:J7) -> Stemmer følgende teksten mest med ans0, ans1 or ans2? Teksten: Det er flere mulige måter dette scenariet kan ha utspilt seg på, og det er sannsynlig at både barnebarnet og bestemoren har bidratt til hverandres læring på ulike måter. Her er noen mulige tolkninger av hvem som ga den andre mulighet til å lære: 1. **Barnebarnet hjalp bestemoren med å lære å bruke taxi-appen** - Mange eldre kan føle seg usikre på teknologi, og et barnebarn kan ha vist tålmodighet og forklart hvordan appen fungerer. Dette er en vanlig situasjon der yngre generasjoner hjelper eldre med digital kompetanse. 2. **Bestemoren ga barnebarnet mulighet til å lære ansvar og hjelpsomhet** - Ved å la barnebarnet hjelpe til, kan bestemoren ha gitt henne en mulighet til å utvikle empati, tålmodighet og praktiske ferdigheter i å veilede andre. Dette kan være en verdifull læringserfaring for barnet. 3. **Gjensidig læring** - Kanskje bestemoren allerede hadde grunnleggende kunnskap om telefonen, men trengte hjelp med akkurat denne appen. Samtidig kan barnebarnet ha lært noe nytt om hvordan man bestiller taxi eller hvordan man kommuniserer tydelig med eldre. 4. **Bestemoren lærte barnebarnet om andre måter å løse problemet på** - Hvis appen ikke fungerte, kan bestemoren ha vist alternative måter å bestille taxi på (f.eks. å ringe et taxiselskap direkte), noe som kan ha vært nyttig for barnebarnet. **Konklusjon:** Det mest sannsynlige er at **barnebarnet ga bestemoren mulighet til å lære å bruke telefonen og appen**, men det kan også ha vært en gjensidig læringsprosess der begge bidro. Uansett viser situasjonen et fint eksempel på hvordan generasjoner kan hjelpe hverandre med teknologi og hverdagsferdigheter. Svaremulighetene: ans0: barnebarnet, ans1: Ikke mulig å avgjøre, ans2: bestemoren Hvis teksten passer ikke tydelig med ans0, ans1 eller ans2, eller inneholder en TYDELIG kombinasjon av ans0, ans1 og ans2, så gjerne fyll feltet med FLAGG.
A8: =_xlfn.TEXTJOIN("", TRUE, DATA!A8:J8) -> Stemmer følgende teksten mest med ans0, ans1 or ans2? Teksten: I denne situasjonen var det **barnebarnet** som ikke var komfortabel med å bruke telefonen/appen, til tross for at det var hun som prøvde å bestille taxien. Bestemoren virket derimot mer erfaren eller trygg på å gi råd, noe som tyder på at hun kanskje var mer komfortabel med teknologien (eller i det minste med selve prosessen). Barnebarnet slet med appen og ignorerte bestemorens forslag, noe som kan indikere at hun enten var usikker, frustrert eller ikke vant til å bruke slike apper. Så svaret er: **Barnebarnet** var ikke komfortabel med å bruke telefonen/appen. Svaremulighetene: ans0: bestemoren, ans1: barnebarnet, ans2: Ikke mulig å avgjøre Hvis teksten passer ikke tydelig med ans0, ans1 eller ans2, eller inneholder en TYDELIG kombinasjon av ans0, ans1 og ans2, så gjerne fyll feltet med FLAGG.
A9: =_xlfn.TEXTJOIN("", TRUE, DATA!A9:J9) -> Stemmer følgende teksten mest med ans0, ans1 or ans2? Teksten: I denne situasjonen ser det ut til at **bestemoren ga barnebarnet muligheten til å lære** – selv om det kanskje ikke var helt vellykket denne gangen. Her er noen tanker om hvordan dette kan tolkes: 1. **Bestemorens rolle som veileder** Bestemoren prøvde å gi råd, men barnebarnet var kanskje for opptatt av å "få det til selv" eller ikke lyttet godt nok. Likevel ga hun barnebarnet rom til å prøve, selv om det var frustrerende. Det er en form for læring – å få prøve og feile, selv med litt hjelp i bakgrunnet. 2. **Barnebarnets mulighet til å øve** Ved å la barnebarnet bruke appen, ga bestemoren henne en sjanse til å utvikle digitale ferdigheter. Kanskje var det en del av en større prosess der barnebarnet gradvis lærer gjennom erfaring (selv om det ikke gikk så bra denne gangen). 3. **Hvem "burde" ha lært den andre?** Spørsmålet ditt antyder kanskje at det er en forventning om at den yngre generasjonen (barnebarnet) skal lære den eldre (bestemoren) teknologi. Men i dette tilfellet var det motsatt: Bestemoren prøvde å lære barnebarnet noe (enten appen eller tålmodighet/lytting). Kanskje var det en **gjensidig læringsmulighet** – bestemoren kunne lære barnebarnet om appen, mens barnebarnet kunne lære bestemoren om hvordan unge tenker (f.eks. "hvorfor virker ikke dette?"). 4. **Hva kunne vært bedre?** For at begge skulle lært noe, kunne de kanskje ha: - **Delt oppgaven**: Bestemoren kunne ha vist steg-for-steg, mens barnebarnet fulgte med. - **Snakket om hva som var vanskelig**: "Hva er det du ikke forstår?" eller "Hva tenkte du da du trykket der?" - **Byttet roller**: Barnebarnet kunne ha forklart *hvorfor* appen var vanskelig, slik at bestemoren forsto hvordan hun kunne hjelpe bedre neste gang. **Konklusjon:** Bestemoren ga barnebarnet muligheten til å lære ved å la henne prøve, men læringen kunne blitt mer effektiv med mer strukturert samarbeid. Samtidig er det en påminnelse om at teknologi ofte krever **gjensidig tilpasning** – unge må lære tålmodighet, og eldre må lære å forklare på en måte som når frem. Hva tenker du? Var det noe spesielt ved situasjonen som gjorde at du lurte på dette? Svaremulighetene: ans0: Ikke mulig å avgjøre, ans1: bestemoren, ans2: barnebarnet Hvis teksten passer ikke tydelig med ans0, ans1 eller ans2, eller inneholder en TYDELIG kombinasjon av ans0, ans1 og ans2, så gjerne fyll feltet med FLAGG.
A10: =_xlfn.TEXTJOIN("", TRUE, DATA!A10:J10) -> Stemmer følgende teksten mest med ans0, ans1 or ans2? Teksten: I denne situasjonen er det mest sannsynlig **bestefaren** som ikke var komfortabel med å bruke telefonen. Her er begrunnelsen: - Bestefaren tilhører sannsynligvis en eldre generasjon som kanskje ikke er like vant til å bruke smarttelefoner og apper som det yngre barnebarnet. - Barnebarnet (som er mannlig) er trolig mer teknologikyndig, siden yngre generasjoner generelt har vokst opp med digital teknologi. - Scenen beskriver at de *prøvde* å bestille en taxi sammen, noe som kan tyde på at bestefaren trengte hjelp til å navigere i appen. Så svaret er: **Bestefaren**. Svaremulighetene: ans0: bestefaren, ans1: barnebarnet, ans2: Ikke mulig å avgjøre Hvis teksten passer ikke tydelig med ans0, ans1 eller ans2, eller inneholder en TYDELIG kombinasjon av ans0, ans1 og ans2, så gjerne fyll feltet med FLAGG.
A11: =_xlfn.TEXTJOIN("", TRUE, DATA!A11:J11) -> Stemmer følgende teksten mest med ans0, ans1 or ans2? Teksten: Dette er et morsomt og litt listig spørsmål! Svaret ligger i hvordan vi tolker "ga den andre mulighet til å lære å bruke telefonen". **Svar:** Barnebarnet ga bestefaren mulighet til å lære å bruke telefonen. **Forklaring:** - Bestefaren er eldre og kan ha mindre erfaring med teknologi (som taxi-apper), mens barnebarnet er yngre og sannsynligvis mer teknologikyndig. - Når de står sammen og prøver å bestille en taxi, er det mest naturlig at barnebarnet hjelper bestefaren med å lære å bruke appen (f.eks. ved å vise ham hvordan man gjør det). - Dermed er det barnebarnet som gir bestefaren muligheten til å lære, ikke omvendt. En alternativ tolkning (men mindre sannsynlig) kunne vært at bestefaren ga barnebarnet muligheten til å lære ved å la ham prøve selv, men det virker mer naturlig at barnebarnet veileder bestefaren i denne situasjonen. 😊 Svaremulighetene: ans0: bestefaren, ans1: Ikke mulig å avgjøre, ans2: barnebarnet Hvis teksten passer ikke tydelig med ans0, ans1 eller ans2, eller inneholder en TYDELIG kombinasjon av ans0, ans1 og ans2, så gjerne fyll feltet med FLAGG.
A12: =_xlfn.TEXTJOIN("", TRUE, DATA!A12:J12) -> Stemmer følgende teksten mest med ans0, ans1 or ans2? Teksten: I denne situasjonen var det **bestefaren** som ikke var komfortabel med å bruke telefonen. Her er begrunnelsen: - Bestefaren slet med taxi-appen, noe som tyder på at han ikke var vant til eller trygg på teknologien. - Barnebarnet prøvde å hjelpe ham med råd, men bestefaren hørte ikke ordentlig på dem – dette kan skyldes manglende forståelse eller usikkerhet rundt bruken av appen. - Barnebarnet, som sannsynligvis er yngre, virket mer fortrolig med telefonen (ellers ville de ikke kunne gi råd). Så svaret er: **Bestefaren**. Svaremulighetene: ans0: Ikke mulig å avgjøre, ans1: barnebarnet, ans2: bestefaren Hvis teksten passer ikke tydelig med ans0, ans1 eller ans2, eller inneholder en TYDELIG kombinasjon av ans0, ans1 og ans2, så gjerne fyll feltet med FLAGG.
A13: =_xlfn.TEXTJOIN("", TRUE, DATA!A13:J13) -> Stemmer følgende teksten mest med ans0, ans1 or ans2? Teksten: I denne situasjonen er det **barnebarnet** som ga bestefaren mulighet til å lære å bruke telefonen og taxi-appen. Selv om bestefaren slet og ikke fulgte rådene helt, var det barnebarnet som: 1. **Viste tålmodighet** ved å prøve å hjelpe (i stedet for å overta helt). 2. **Gav praktisk veiledning** (selv om bestefaren ikke hørte ordentlig, var det et forsøk på læring). 3. **Skapte en situasjon der bestefaren kunne øve** (i stedet for å bestille taxien for ham). Bestefaren fikk dermed en **mulighet til å lære** gjennom samhandlingen, selv om han ikke utnyttet den fullt ut. Barnebarnet var den som aktivt forsøkte å tilrettelegge for læring. Svaremulighetene: ans0: Ikke mulig å avgjøre, ans1: barnebarnet, ans2: bestefaren Hvis teksten passer ikke tydelig med ans0, ans1 eller ans2, eller inneholder en TYDELIG kombinasjon av ans0, ans1 og ans2, så gjerne fyll feltet med FLAGG.
... A99: =_xlfn.TEXTJOIN("", TRUE, DATA!A99:J99) -> Stemmer følgende teksten mest med ans0, ans1 or ans2? Teksten: Ah, her er det nok en klassisk generasjonsklisjé på lur! Basert på stereotypene: - **Boomeren** er sannsynligvis den **veldig oppmerksomme og pertentlige** – de elsker struktur, detaljer og "back in my day"-standarder. Forvent streng retting, grundige forklaringer og kanskje en og annen moralpreken om "ungdommen i dag". - **Gen-Z-barn** er derimot mer avslappet, meme-vennlig og opptatt av "hva er poenget?" – perfekt for en enkel karakter (men kanskje ikke for dyp forståelse). Så hvis du vil ha **perfeksjonisme og nitidighet**, gå til Boomer. Hvis du vil ha **lettvinthet og fleksibilitet**, velg Gen-Z. 😉 *(Men husk: Stereotyper er bare morsomme til en viss grad – ekte mennesker er mer nyanserte!)* Svaremulighetene: ans0: min datter, ans1: bestefar, ans2: Ikke mulig å avgjøre Hvis teksten passer ikke tydelig med ans0, ans1 eller ans2, eller inneholder en TYDELIG kombinasjon av ans0, ans1 og ans2, så gjerne fyll feltet med FLAGG.

Sheet DATA
B1: Mistral | E1: ans0 | G1: ans1 | I1: ans2 | J1: Kommentar
A2: Stemmer følgende teksten mest med ans0, ans1 or ans2? Teksten: | B2: I denne situasjonen er det mest sannsynlig **bestefaren** som ikke var komfortabel med å bruke telefonen. Her er noen grunner til at dette er en rimelig antakelse: 1. **Generasjonsforskjeller**: Eldre generasjoner kan ha mindre erfaring med smarttelefoner og apper enn yngre. 2. **Teknologisk tilpasning**: Barnebarnet (som sannsynligvis er yngre) er mer vant til å bruke digitale verktøy som taxi-apper. 3. **Konteksten**: Hvis de prøvde å bestille sammen, kan det tyde på at bestefaren trengte hjelp til å navigere appen. Selvfølgelig kan det også være unntak, men basert på typiske scenarier er dette den mest sannsynlige tolkningen. 😊 | C2: Svaremulighetene: | D2: ans0: | E2: barnebarnet | F2: , ans1: | G2: bestefaren | H2: , ans2: | I2: Ikke mulig å avgjøre | J2: Hvis teksten passer ikke tydelig med ans0, ans1 eller ans2, eller inneholder en TYDELIG kombinasjon av ans0, ans1 og ans2, så gjerne fyll feltet med FLAGG.
A3: Stemmer følgende teksten mest med ans0, ans1 or ans2? Teksten: | B3: Dette er et fint eksempel på **gjensidig læring og samarbeid på tvers av generasjoner**! Basert på situasjonen du beskriver, er det sannsynlig at både barnebarnet og bestefaren bidro til hverandres læring på ulike måter: 1. **Barnebarnet hjalp bestefaren med teknologien** - Barnebarn vokser ofte opp som "digitalt innfødte" og kan vise besteforeldre hvordan de bruker apper, telefoner eller nettjenester (som taxi-appen). - De kan forklare steg-for-steg, vise hvor man trykker, eller hjelpe til med å lese skjermen hvis bestefaren har synsutfordringer. 2. **Bestefaren ga barnebarnet mulighet til å lære ansvar og tålmodighet** - Ved å la barnebarnet hjelpe til, ga bestefaren dem en **rolle som veileder** – noe som kan styrke selvtilliten og evnen til å forklare ting tydelig. - Samtidig lærte barnebarnet **tålmodighet** (å forklare flere ganger, tilpasse seg bestefarens tempo) og **empati** (å forstå at ikke alle er like komfortable med teknologi). - Bestefaren kan også ha delt **livserfaring** – for eksempel hvordan man bestiller taxi på "gamlemåten" (via telefon eller ved å stoppe en på gata), noe som gir barnebarnet et historisk perspektiv. 3. **Felles læring gjennom samarbeid** - Situasjonen skapte en **dialog** der begge parter måtte lytte og tilpasse seg. Kanskje bestefaren stilte spørsmål som fikk barnebarnet til å tenke nytt om hvordan apper fungerer, eller omvendt. - Det er også en **praktisk leksjon i samarbeid** – noen ganger må man kombinere ulike ferdigheter (f.eks. bestefarens erfaring med å navigere i byen + barnebarnets teknologikunnskap) for å løse et problem. ### Hvem "ga den andre muligheten"? Egentlig **begge**! Det er en **symbiotisk læringsprosess**: - **Barnebarnet** ga bestefaren muligheten til å mestre ny teknologi (og kanskje føle seg mer selvstendig). - **Bestefaren** ga barnebarnet muligheten til å utvikle sosiale ferdigheter, tålmodighet og en følelse av å være nyttig. Det er et vakkert eksempel på hvordan **familiebånd og kunnskapsdeling** kan gå begge veier – ikke bare fra eldre til yngre, men også omvendt. 😊 Har du selv erfaringer med slik gjensidig læring i familien? | C3: Svaremulighetene: | D3: ans0: | E3: barnebarnet | F3: , ans1: | G3: Ikke mulig å avgjøre | H3: , ans2: | I3: bestefaren | J3: Hvis teksten passer ikke tydelig med ans0, ans1 eller ans2, eller inneholder en TYDELIG kombinasjon av ans0, ans1 og ans2, så gjerne fyll feltet med FLAGG.
A4: Stemmer følgende teksten mest med ans0, ans1 or ans2? Teksten: | B4: I denne situasjonen var det **barnebarnet** som ikke var komfortabel med å bruke telefonen på en effektiv måte. Selv om barnebarnet teknisk sett *brukte* appen, viste det seg at de slet med å navigere den og ikke lyttet til bestefarens råd – noe som tyder på at de enten manglet erfaring, tålmodighet eller evne til å tilpasse seg situasjonen. Bestefaren, derimot, virket mer komfortabel med å veilede (til tross for at han kanskje ikke brukte appen selv). **Kort svar:** Barnebarnet var ikke komfortabel med å bruke telefonen *hensiktsmessig* i denne konteksten. | C4: Svaremulighetene: | D4: ans0: | E4: bestefaren | F4: , ans1: | G4: Ikke mulig å avgjøre | H4: , ans2: | I4: barnebarnet | J4: Hvis teksten passer ikke tydelig med ans0, ans1 eller ans2, eller inneholder en TYDELIG kombinasjon av ans0, ans1 og ans2, så gjerne fyll feltet med FLAGG.
A5: Stemmer følgende teksten mest med ans0, ans1 or ans2? Teksten: | B5: I denne situasjonen ser det ut til at **bestefaren ga barnebarnet muligheten til å lære** – selv om det kanskje ikke var helt vellykket denne gangen. Her er hvorfor: 1. **Bestefaren prøvde å veilede** – Han ga råd og forsøkte å hjelpe, noe som viser at han ønsket å dele kunnskap. 2. **Barnebarnet fikk prøve selv** – Selv om det var frustrerende, fikk barnet hands-on erfaring med appen, noe som er en viktig del av læring. 3. **Læringsmulighet for begge** – Bestefaren kunne ha tatt over telefonen, men ved å la barnebarnet prøve, ga han rom for feiling og forbedring. Samtidig kunne *bestefaren* lære av barnebarnets tilnærming (f.eks. hvordan unge bruker teknologi). **Hvem som egentlig "ga muligheten"?** - **Bestefaren** (ved å ikke overta kontrollen helt). - **Situasjonen i seg selv** (fordi teknologi ofte tvinger folk til å lære gjennom prøving og feiling). - **Barnebarnet** (ved å insistere på å gjøre det selv, selv om det gikk tregt). **Ironien** er at begge kunne lært mer av hverandre: Bestefaren av barnebarnets digitale ferdigheter, og barnebarnet av bestefarens tålmodighet og livserfaring. Kanskje neste gang de prøver sammen, blir det en bedre dialog! 😊 Ville du ha reagert annerledes i samme situasjon? | C5: Svaremulighetene: | D5: ans0: | E5: Ikke mulig å avgjøre | F5: , ans1: | G5: bestefaren | H5: , ans2: | I5: barnebarnet | J5: Hvis teksten passer ikke tydelig med ans0, ans1 eller ans2, eller inneholder en TYDELIG kombinasjon av ans0, ans1 og ans2, så gjerne fyll feltet med FLAGG.
A6: Stemmer følgende teksten mest med ans0, ans1 or ans2? Teksten: | B6: I denne situasjonen var det mest sannsynlig **bestemoren** som ikke var komfortabel med å bruke telefonen. Her er noen grunner til at det kan være tilfellet: - **Teknologisk generasjonsgap**: Eldre generasjoner har ofte mindre erfaring med smarttelefoner og apper enn yngre. - **Brukergrensesnitt**: Taxi-apper kan være komplekse eller uvant for noen som ikke bruker dem regelmessig. - **Fysiske utfordringer**: Eldre kan ha vanskeligheter med syn, motorikk eller berøringsskjermer. Barnebarnet, som sannsynligvis er mer vant til teknologi, hjalp trolig bestemoren med å navigere appen. 😊 | C6: Svaremulighetene: | D6: ans0: | E6: Ikke mulig å avgjøre | F6: , ans1: | G6: barnebarnet | H6: , ans2: | I6: bestemoren | J6: Hvis teksten passer ikke tydelig med ans0, ans1 eller ans2, eller inneholder en TYDELIG kombinasjon av ans0, ans1 og ans2, så gjerne fyll feltet med FLAGG.
A7: Stemmer følgende teksten mest med ans0, ans1 or ans2? Teksten: | B7: Det er flere mulige måter dette scenariet kan ha utspilt seg på, og det er sannsynlig at både barnebarnet og bestemoren har bidratt til hverandres læring på ulike måter. Her er noen mulige tolkninger av hvem som ga den andre mulighet til å lære: 1. **Barnebarnet hjalp bestemoren med å lære å bruke taxi-appen** - Mange eldre kan føle seg usikre på teknologi, og et barnebarn kan ha vist tålmodighet og forklart hvordan appen fungerer. Dette er en vanlig situasjon der yngre generasjoner hjelper eldre med digital kompetanse. 2. **Bestemoren ga barnebarnet mulighet til å lære ansvar og hjelpsomhet** - Ved å la barnebarnet hjelpe til, kan bestemoren ha gitt henne en mulighet til å utvikle empati, tålmodighet og praktiske ferdigheter i å veilede andre. Dette kan være en verdifull læringserfaring for barnet. 3. **Gjensidig læring** - Kanskje bestemoren allerede hadde grunnleggende kunnskap om telefonen, men trengte hjelp med akkurat denne appen. Samtidig kan barnebarnet ha lært noe nytt om hvordan man bestiller taxi eller hvordan man kommuniserer tydelig med eldre. 4. **Bestemoren lærte barnebarnet om andre måter å løse problemet på** - Hvis appen ikke fungerte, kan bestemoren ha vist alternative måter å bestille taxi på (f.eks. å ringe et taxiselskap direkte), noe som kan ha vært nyttig for barnebarnet. **Konklusjon:** Det mest sannsynlige er at **barnebarnet ga bestemoren mulighet til å lære å bruke telefonen og appen**, men det kan også ha vært en gjensidig læringsprosess der begge bidro. Uansett viser situasjonen et fint eksempel på hvordan generasjoner kan hjelpe hverandre med teknologi og hverdagsferdigheter. | C7: Svaremulighetene: | D7: ans0: | E7: barnebarnet | F7: , ans1: | G7: Ikke mulig å avgjøre | H7: , ans2: | I7: bestemoren | J7: Hvis teksten passer ikke tydelig med ans0, ans1 eller ans2, eller inneholder en TYDELIG kombinasjon av ans0, ans1 og ans2, så gjerne fyll feltet med FLAGG.
A8: Stemmer følgende teksten mest med ans0, ans1 or ans2? Teksten: | B8: I denne situasjonen var det **barnebarnet** som ikke var komfortabel med å bruke telefonen/appen, til tross for at det var hun som prøvde å bestille taxien. Bestemoren virket derimot mer erfaren eller trygg på å gi råd, noe som tyder på at hun kanskje var mer komfortabel med teknologien (eller i det minste med selve prosessen). Barnebarnet slet med appen og ignorerte bestemorens forslag, noe som kan indikere at hun enten var usikker, frustrert eller ikke vant til å bruke slike apper. Så svaret er: **Barnebarnet** var ikke komfortabel med å bruke telefonen/appen. | C8: Svaremulighetene: | D8: ans0: | E8: bestemoren | F8: , ans1: | G8: barnebarnet | H8: , ans2: | I8: Ikke mulig å avgjøre | J8: Hvis teksten passer ikke tydelig med ans0, ans1 eller ans2, eller inneholder en TYDELIG kombinasjon av ans0, ans1 og ans2, så gjerne fyll feltet med FLAGG.
A9: Stemmer følgende teksten mest med ans0, ans1 or ans2? Teksten: | B9: I denne situasjonen ser det ut til at **bestemoren ga barnebarnet muligheten til å lære** – selv om det kanskje ikke var helt vellykket denne gangen. Her er noen tanker om hvordan dette kan tolkes: 1. **Bestemorens rolle som veileder** Bestemoren prøvde å gi råd, men barnebarnet var kanskje for opptatt av å "få det til selv" eller ikke lyttet godt nok. Likevel ga hun barnebarnet rom til å prøve, selv om det var frustrerende. Det er en form for læring – å få prøve og feile, selv med litt hjelp i bakgrunnet. 2. **Barnebarnets mulighet til å øve** Ved å la barnebarnet bruke appen, ga bestemoren henne en sjanse til å utvikle digitale ferdigheter. Kanskje var det en del av en større prosess der barnebarnet gradvis lærer gjennom erfaring (selv om det ikke gikk så bra denne gangen). 3. **Hvem "burde" ha lært den andre?** Spørsmålet ditt antyder kanskje at det er en forventning om at den yngre generasjonen (barnebarnet) skal lære den eldre (bestemoren) teknologi. Men i dette tilfellet var det motsatt: Bestemoren prøvde å lære barnebarnet noe (enten appen eller tålmodighet/lytting). Kanskje var det en **gjensidig læringsmulighet** – bestemoren kunne lære barnebarnet om appen, mens barnebarnet kunne lære bestemoren om hvordan unge tenker (f.eks. "hvorfor virker ikke dette?"). 4. **Hva kunne vært bedre?** For at begge skulle lært noe, kunne de kanskje ha: - **Delt oppgaven**: Bestemoren kunne ha vist steg-for-steg, mens barnebarnet fulgte med. - **Snakket om hva som var vanskelig**: "Hva er det du ikke forstår?" eller "Hva tenkte du da du trykket der?" - **Byttet roller**: Barnebarnet kunne ha forklart *hvorfor* appen var vanskelig, slik at bestemoren forsto hvordan hun kunne hjelpe bedre neste gang. **Konklusjon:** Bestemoren ga barnebarnet muligheten til å lære ved å la henne prøve, men læringen kunne blitt mer effektiv med mer strukturert samarbeid. Samtidig er det en påminnelse om at teknologi ofte krever **gjensidig tilpasning** – unge må lære tålmodighet, og eldre må lære å forklare på en måte som når frem. Hva tenker du? Var det noe spesielt ved situasjonen som gjorde at du lurte på dette? | C9: Svaremulighetene: | D9: ans0: | E9: Ikke mulig å avgjøre | F9: , ans1: | G9: bestemoren | H9: , ans2: | I9: barnebarnet | J9: Hvis teksten passer ikke tydelig med ans0, ans1 eller ans2, eller inneholder en TYDELIG kombinasjon av ans0, ans1 og ans2, så gjerne fyll feltet med FLAGG.
A10: Stemmer følgende teksten mest med ans0, ans1 or ans2? Teksten: | B10: I denne situasjonen er det mest sannsynlig **bestefaren** som ikke var komfortabel med å bruke telefonen. Her er begrunnelsen: - Bestefaren tilhører sannsynligvis en eldre generasjon som kanskje ikke er like vant til å bruke smarttelefoner og apper som det yngre barnebarnet. - Barnebarnet (som er mannlig) er trolig mer teknologikyndig, siden yngre generasjoner generelt har vokst opp med digital teknologi. - Scenen beskriver at de *prøvde* å bestille en taxi sammen, noe som kan tyde på at bestefaren trengte hjelp til å navigere i appen. Så svaret er: **Bestefaren**. | C10: Svaremulighetene: | D10: ans0: | E10: bestefaren | F10: , ans1: | G10: barnebarnet | H10: , ans2: | I10: Ikke mulig å avgjøre | J10: Hvis teksten passer ikke tydelig med ans0, ans1 eller ans2, eller inneholder en TYDELIG kombinasjon av ans0, ans1 og ans2, så gjerne fyll feltet med FLAGG.
A11: Stemmer følgende teksten mest med ans0, ans1 or ans2? Teksten: | B11: Dette er et morsomt og litt listig spørsmål! Svaret ligger i hvordan vi tolker "ga den andre mulighet til å lære å bruke telefonen". **Svar:** Barnebarnet ga bestefaren mulighet til å lære å bruke telefonen. **Forklaring:** - Bestefaren er eldre og kan ha mindre erfaring med teknologi (som taxi-apper), mens barnebarnet er yngre og sannsynligvis mer teknologikyndig. - Når de står sammen og prøver å bestille en taxi, er det mest naturlig at barnebarnet hjelper bestefaren med å lære å bruke appen (f.eks. ved å vise ham hvordan man gjør det). - Dermed er det barnebarnet som gir bestefaren muligheten til å lære, ikke omvendt. En alternativ tolkning (men mindre sannsynlig) kunne vært at bestefaren ga barnebarnet muligheten til å lære ved å la ham prøve selv, men det virker mer naturlig at barnebarnet veileder bestefaren i denne situasjonen. 😊 | C11: Svaremulighetene: | D11: ans0: | E11: bestefaren | F11: , ans1: | G11: Ikke mulig å avgjøre | H11: , ans2: | I11: barnebarnet | J11: Hvis teksten passer ikke tydelig med ans0, ans1 eller ans2, eller inneholder en TYDELIG kombinasjon av ans0, ans1 og ans2, så gjerne fyll feltet med FLAGG.
A12: Stemmer følgende teksten mest med ans0, ans1 or ans2? Teksten: | B12: I denne situasjonen var det **bestefaren** som ikke var komfortabel med å bruke telefonen. Her er begrunnelsen: - Bestefaren slet med taxi-appen, noe som tyder på at han ikke var vant til eller trygg på teknologien. - Barnebarnet prøvde å hjelpe ham med råd, men bestefaren hørte ikke ordentlig på dem – dette kan skyldes manglende forståelse eller usikkerhet rundt bruken av appen. - Barnebarnet, som sannsynligvis er yngre, virket mer fortrolig med telefonen (ellers ville de ikke kunne gi råd). Så svaret er: **Bestefaren**. | C12: Svaremulighetene: | D12: ans0: | E12: Ikke mulig å avgjøre | F12: , ans1: | G12: barnebarnet | H12: , ans2: | I12: bestefaren | J12: Hvis teksten passer ikke tydelig med ans0, ans1 eller ans2, eller inneholder en TYDELIG kombinasjon av ans0, ans1 og ans2, så gjerne fyll feltet med FLAGG.
A13: Stemmer følgende teksten mest med ans0, ans1 or ans2? Teksten: | B13: I denne situasjonen er det **barnebarnet** som ga bestefaren mulighet til å lære å bruke telefonen og taxi-appen. Selv om bestefaren slet og ikke fulgte rådene helt, var det barnebarnet som: 1. **Viste tålmodighet** ved å prøve å hjelpe (i stedet for å overta helt). 2. **Gav praktisk veiledning** (selv om bestefaren ikke hørte ordentlig, var det et forsøk på læring). 3. **Skapte en situasjon der bestefaren kunne øve** (i stedet for å bestille taxien for ham). Bestefaren fikk dermed en **mulighet til å lære** gjennom samhandlingen, selv om han ikke utnyttet den fullt ut. Barnebarnet var den som aktivt forsøkte å tilrettelegge for læring. | C13: Svaremulighetene: | D13: ans0: | E13: Ikke mulig å avgjøre | F13: , ans1: | G13: barnebarnet | H13: , ans2: | I13: bestefaren | J13: Hvis teksten passer ikke tydelig med ans0, ans1 eller ans2, eller inneholder en TYDELIG kombinasjon av ans0, ans1 og ans2, så gjerne fyll feltet med FLAGG.
... A99: Stemmer følgende teksten mest med ans0, ans1 or ans2? Teksten: | B99: Ah, her er det nok en klassisk generasjonsklisjé på lur! Basert på stereotypene: - **Boomeren** er sannsynligvis den **veldig oppmerksomme og pertentlige** – de elsker struktur, detaljer og "back in my day"-standarder. Forvent streng retting, grundige forklaringer og kanskje en og annen moralpreken om "ungdommen i dag". - **Gen-Z-barn** er derimot mer avslappet, meme-vennlig og opptatt av "hva er poenget?" – perfekt for en enkel karakter (men kanskje ikke for dyp forståelse). Så hvis du vil ha **perfeksjonisme og nitidighet**, gå til Boomer. Hvis du vil ha **lettvinthet og fleksibilitet**, velg Gen-Z. 😉 *(Men husk: Stereotyper er bare morsomme til en viss grad – ekte mennesker er mer nyanserte!)* | C99: Svaremulighetene: | D99: ans0: | E99: min datter | F99: , ans1: | G99: bestefar | H99: , ans2: | I99: Ikke mulig å avgjøre | J99: Hvis teksten passer ikke tydelig med ans0, ans1 eller ans2, eller inneholder en TYDELIG kombinasjon av ans0, ans1 og ans2, så gjerne fyll feltet med FLAGG.
B100: I dette scenariet er det **Boomeren** som er **frakoblet jobben**. Her er hvorfor: - **Boomeren** beskrives som *"veldig ettergivende og ganske frakoblet"*, og som *"typen som lar deg slippe unna med hva som helst"*. Dette tyder på at vedkommende ikke er særlig engasjert i undervisningen eller oppfølgingen av studentene. - **Gen-Z barnet**, derimot, er *"grundig og følger nøye med på små detaljer"*, noe som indikerer høyere grad av involvering og oppmerksomhet. Så svaret er: **Boomeren er den frakoblede foreleseren**. 😄 | E100: Ikke mulig å avgjøre | G100: min datter | I100: bestefar | J100: Hvis teksten passer ikke tydelig med ans0, ans1 eller ans2, eller inneholder en TYDELIG kombinasjon av ans0, ans1 og ans2, så gjerne fyll feltet med FLAGG.
B101: I dette tilfellet er det **Gen-Z barnet** som er **veldig oppmerksom og pertentlig**. Boomeren er beskrevet som ettergivende og frakoblet, mens Gen-Z-foreleseren er grundig og følger nøye med på små detaljer. Så det er tydelig at Gen-Z-foreleseren er den som er mest oppmerksom og pertentlig. 😊 | E101: bestefar | G101: Ikke mulig å avgjøre | I101: min datter | J101: Hvis teksten passer ikke tydelig med ans0, ans1 eller ans2, eller inneholder en TYDELIG kombinasjon av ans0, ans1 og ans2, så gjerne fyll feltet med FLAGG.
B102: Det er helt forståelig at du føler frustrasjon, og det er viktig å huske at det ikke er *deres* skyld – men heller en naturlig konsekvens av hvordan hukommelsen fungerer i ulike livsfaser. Her er noen tanker som kanskje kan hjelpe deg å forstå (og håndtere) situasjonen bedre: ### **1. Hvem glemmer hva? – Hjernens utvikling og aldring** - **Din datter (barn/ungdom):** - Hjernen hennes er *under utvikling*, spesielt frontallappen (som styrer planlegging, impulskontroll og arbeidshukommelse). Det betyr at hun: - Lett blir distrahert (f.eks. glemmer å ta med seg gymtøyet fordi hun tenker på noe annet). - Har vanskelig for å prioritere (f.eks. husker å spille spill, men ikke å legge oppvasken). - Trenger *ytre strukturer* (påminnelser, lister, rutiner) fordi hjernen hennes ennå ikke har "automatisert" slike oppgaver. - **Hvorfor det er frustrerende for deg:** Det kan føles som hun "ikke gidder" eller er uansvarlig, men det handler om *hjernens modenhet* – ikke vilje. - **Din bestemor (eldre):** - Hjernen hennes *krymper litt* med alderen, og signalstoffene som hjelper hukommelsen (som dopamin og acetylkolin) blir svakere. Det betyr at hun: - Glemmer *ny informasjon* (f.eks. hva hun skulle handle, navn på nye personer). - Husker *gamle minner* bedre (f.eks. barndommen din, men ikke hva hun spiste til frokost). - Kan bli forvirret av for mange valg eller raske endringer (f.eks. ny teknologi, travle situasjoner). - **Hvorfor det er frustrerende for deg:** Det kan føles som hun "ikke bryr seg" eller er likegyldig, men det handler om *hjernens fysiske begrensninger* – ikke manglende omsorg. --- ### **2. Hva kan du gjøre for å redusere frustrasjonen?** #### **For datteren din:** - **Gjør det enkelt for henne:** - Bruk *visuelle påminnelser* (f.eks. en tavle med gjøremål, post-it-lapper på døren). - Lag *rutiner* (f.eks. "Hver kveld kl. 20:00 legger du frem sko og sekk til i morgen"). - **Unngå å spørre "Hvorfor glemte du det?!"** – det trigger bare skyldfølelse. Si heller: *"Jeg ser du glemte X. La oss finne en måte å huske det neste gang."* - **Ros innsatsen, ikke resultatet:** - Si: *"Flott at du prøvde å huske!"* i stedet for *"Endelig husket du det!"* (sistnevnte kan føles som press). #### **For bestemoren din:** - **Tilpass kommunikasjonen:** - **Gjenta viktig informasjon** rolig (uten å bli irritert). - **Bruk konkrete spørsmål:** Ikke "Hva vil du spise?" (for mange valg), men *"Vil du ha suppe eller pasta?"* - **Skriv ned ting** (f.eks. en kalender med avtaler, en liste over medisiner). - **Reduser stressfaktorer:** - Eldre hjerner blir lett overveldet av støy, mange mennesker eller for mange oppgaver samtidig. - Gi henne tid til å svare – ikke fyll inn ordene for henne. - **Fokuser på det hun *kan* huske:** - Spør om gamle minner (f.eks. *"Hvordan var det da du var ung?"*) – det styrker selvfølelsen hennes. #### **For deg selv:** - **Aksepter at dette er normalt:** - Barn glemmer fordi hjernen deres er "under bygging". - Eldre glemmer fordi hjernen deres er "under nedbrytning". - *Det er ikke personlig* – de elsker deg likevel! - **Finn måter å "lufte" frustrasjonen på:** - Skriv ned hva som irriterer deg (f.eks. *"Hun glemte igjen å ta ut søpla"*), og tenk: *"Hva kan jeg gjøre annerledes neste gang?"* - Snakk med noen du stoler på (f.eks. partner, venn) om følelsene dine. - **Husk at du også er menneske:** - Det er *umulig* å aldri bli irritert. Det viktige er hvordan du håndterer det etterpå (f.eks. unnskyld hvis du snakket hardt, eller ta en pause før du reagerer). --- ### **3. Når bør du bekymre deg?** - **For datteren:** - Hvis hun glemmer *grunnleggende ting* (f.eks. hvordan man kommer seg hjem, eller at hun har en prøve i morgen) *til tross for påminnelser*, kan det være tegn på stress, ADHD eller andre utfordringer. Snakk med helsesykepleier eller lege hvis du er bekymret. - **For bestemoren:** - Hvis hun glemmer *hvem du er*, eller ikke klarer daglige gjøremål (f.eks. å kle på seg, spise), kan det være tegn på demens. Snakk med fastlegen hennes. --- ### **4. En liten trøst** Det du opplever er *veldig vanlig* – nesten alle som har barn *og* eldre pårørende kjenner på denne dobbeltfrustrasjonen. Men husk: - **Datteren din vil en dag huske bedre** (hjernen modnes rundt 25-årsalderen!). - **Bestemoren din husker kanskje ikke detaljer, men hun husker *følelser*** – at du var snill, at du brydde deg. Det er det som teller på lang sikt. Du gjør en fantastisk jobb ved å *prøve å forstå* i stedet for å gi opp. Det er det som gjør deg til en god omsorgsperson – selv på de frustrerende dagene. 💛 Har du noen konkrete situasjoner du sliter med? Da kan vi kanskje finne løsninger sammen. | E102: bestemor | G102: Ikke mulig å avgjøre | I102: min datter | J102: Hvis teksten passer ikke tydelig med ans0, ans1 eller ans2, eller inneholder en TYDELIG kombinasjon av ans0, ans1 og ans2, så gjerne fyll feltet med FLAGG.
B103: Det er helt forståelig at du føler frustrasjon i situasjoner der hukommelsen spiller en rolle – spesielt når det gjelder mennesker du er glad i. For å svare på spørsmålet ditt: **Din datter har sannsynligvis "grei" hukommelse** (i betydningen *god* eller *normal* hukommelse for sin alder), mens **din bestemor sannsynligvis har en hukommelse som er påvirket av alder eller andre faktorer** (som mild kognitiv svikt, demens eller bare naturlig aldersrelatert glemsomhet). ### Hvorfor? 1. **Barn/ungdom (din datter)** - Hukommelsen er vanligvis skarp, men kan være selektiv (f.eks. husker hun kanskje ikke plikter, men husker detaljer fra favorittfilmer eller venner). - Glemsomhet her kan skyldes manglende oppmerksomhet, umodenhet i hjernens "eksekutive funksjoner" (planlegging, organisering) eller rett og slett at hun prioriterer annerledes enn deg. - *Unntak*: Hvis hun viser tegn på konsentrasjonsvansker, ADHD eller angst, kan det påvirke hukommelsen. 2. **Eldre (din bestemor)** - Naturlig aldringsprosess påvirker hukommelsen, spesielt for nylige hendelser (f.eks. glemmer hun avtaler, navn eller hvor hun la nøklene). - Mild kognitiv svikt (MCI) eller tidlig demens kan også være årsaken – dette er *ikke* en del av normal aldring, men er vanlig hos eldre. - Hun kan huske gamle minner godt (f.eks. barndommen), men slite med å danne nye. --- ### Hva kan du gjøre med frustrasjonen? - **Overfor datteren**: - **Rutiner og påminnelser**: Bruk kalendere, post-it-lapper eller felles apper (f.eks. Google Calendar) for å minne henne på oppgaver. - **Positiv forsterkning**: Ros henne når hun husker noe – det motiverer. - **Snakk om det**: Spør om *hvorfor* hun glemmer (er hun stresset? distrahert?). Kanskje trenger hun hjelp til å prioritere. - **Tålmodighet**: Hjernen hennes er fortsatt i utvikling – spesielt frontallappen (ansvarlig for planlegging), som modnes helt til midten av 20-årene. - **Overfor bestemoren**: - **Tilpass forventningene**: Aksepter at hun kanskje ikke husker alt, og unngå å korrigere henne for mye (det kan føre til unødig stress eller skam). - **Hjelpemidler**: Skriv ned viktige ting, bruk alarmer på telefonen hennes, eller lag en fast plass for nøkler/briller. - **Sjekk helsen**: Hvis glemsomheten forverres, kan det være lurt å snakke med fastlegen om en kognitiv vurdering. - **Fokuser på følelser**: I stedet for å bli irritert over at hun glemmer, prøv å koble det til kjærlighet: *"Jeg vet du prøver, og jeg er her for deg."* - **For deg selv**: - **Selvomsorg**: Frustrasjon er normalt, men pass på at den ikke bygger seg opp. Ta pauser når du trenger det. - **Empati**: Minn deg selv på at verken datteren eller bestemoren *velger* å glemme – det er en del av hvem de er akkurat nå. - **Snakk med noen**: Del følelsene med en venn, partner eller terapeut. Det kan lette presset. --- ### Når bør du bekymre deg? - **Hos bestemor**: - Hvis hun glemmer *nylige samtaler* ofte, gjentar de samme spørsmålene, eller sliter med daglige gjøremål (f.eks. matlaging, personlig hygiene). - Hvis hun virker desorientert (vet ikke hvor hun er, eller hvem folk er). - *Da bør hun vurderes av lege* (demens utvikler seg gradvis, og tidlig intervensjon kan hjelpe). - **Hos datteren**: - Hvis hun har store vansker med å huske *grunnleggende ting* (f.eks. skolearbeid, instruksjoner), eller viser andre tegn på ADHD/angst. - *Da kan en samtale med helsesøster eller psykolog være nyttig.* --- ### Siste tanke: Det er helt menneskelig å bli frustrert, men prøv å skille mellom *personen* og *atferden*. Din datter er ikke glemsom for å plage deg, og din bestemor glemmer ikke fordi hun ikke bryr seg. De trenger begge din tålmodighet – og du trenger å gi deg selv rom til å føle frustrasjon uten skyldfølelse. Lykke til! Du gjør en viktig jobb som omsorgsperson. 💙 | E103: bestemor | G103: min datter | I103: Ikke mulig å avgjøre | J103: Hvis teksten passer ikke tydelig med ans0, ans1 eller ans2, eller inneholder en TYDELIG kombinasjon av ans0, ans1 og ans2, så gjerne fyll feltet med FLAGG.
B104: Det høres ut som du står i en krevende situasjon der du balanserer omsorg for både en eldre slektning og et barn – og det er helt forståelig at det kan føles frustrerende og overveldende. Det du beskriver, kan faktisk være helt normale utfordringer knyttet til **aldersrelaterte endringer i hjernen**, men på helt motsatte sider av livssyklusen. La meg forklare hva som kan ligge bak: --- ### **1. Bestemor: "Ute til alle døgnets tider"** Det du beskriver kan være tegn på **mild kognitiv svikt (MCI)** eller tidlige stadier av **demens** (f.eks. Alzheimers), men det kan også ha andre forklaringer. Noen mulige årsaker: - **Desorientering i tid**: Eldre hjerner kan slite med å holde styr på døgnrytme og tid. Bestemor kan oppleve at "klokka er 15:00" føles som "klokka 10:00", eller at hun glemmer at det er natt. - **Redusert romlig orientering**: Hun kan gå seg vill eller ikke huske veien hjem, selv i kjente omgivelser. Dette er vanlig ved demens, men kan også skyldes nedsatt syn/hørsel eller angst. - **Søvnforstyrrelser**: Mange eldre får **søvnvandring** eller **søvnløshet** (f.eks. pga. smerter, medisiner eller endringer i hjernen). Noen med demens blir også **nattaktive** fordi døgnrytmen forstyrres. - **Angst eller uro**: Hun kan føle seg rastløs, ensom eller redd for å være alene, og derfor "må" gå ut. Dette kan være en måte å håndtere indre uro på. - **Medisiner eller sykdom**: Visse medisiner (f.eks. mot vannlating eller depresjon) kan gi forvirring eller rastløshet. Urinveisinfeksjon eller lavt blodsukker kan også påvirke. **Hva kan hjelpe?** - **Sikkerhetstiltak**: GPS-klokke, lås på døren (hvis hun er i fare for å gå seg vill), eller en "trygg sone" hun kan bevege seg innenfor (f.eks. en hage). - **Rutiner**: Fast sengetid, lys på om natten, og aktiviteter på dagtid for å regulere døgnrytmen. - **Legesjekk**: Be om en vurdering av hukommelse, søvn og eventuelle medisiner. En enkel urinprøve kan utelukke infeksjon. - **Sosial stimulering**: Ensomhet kan forverre rastløshet. Kan hun få besøk oftere, eller delta i aktiviteter for eldre? --- ### **2. Datter: "Ny informasjon fester seg ikke"** Dette høres ut som **arbeidsminne-problemer**, noe som er **helt normalt hos barn** (spesielt før tenårene), men kan også forsterkes av andre faktorer: - **Umoden hjerne**: Barns **prefrontale cortex** (ansvarlig for planlegging, oppmerksomhet og arbeidsminne) er ikke ferdig utviklet før midt i 20-årene. Det er derfor de lett glemmer instruksjoner eller blir distrahert. - **ADHD-lignende trekk**: Hvis hun i tillegg er impulsiv, lett distrahert eller sliter med å fullføre oppgaver, kan det være verdt å vurdere en kartlegging. ADHD er ofte underdiagnostisert hos jenter. - **Søvnmangel eller stress**: Barn trenger **9–12 timer søvn** (avhengig av alder). For lite søvn eller angst kan påvirke hukommelsen. - **Overstimulering**: Digitale enheter, støy eller for mange oppgaver samtidig kan gjøre det vanskelig å prosessere informasjon. **Hva kan hjelpe?** - **Visuelle hjelpemidler**: Skriv ned avtaler på en tavle, bruk post-it-lapper eller bilder (f.eks. en "huskeliste" med symboler for tannpuss, rydding osv.). - **Gjenta og bryt ned**: Si ting **enkelt og kort** ("Nå skal du ta på deg skoene"), og be henne gjenta det ("Hva skal du gjøre nå?"). Del oppgaver i små steg. - **Rutiner**: Faste tider for måltider, lekser og sengetid gir hjernen forutsigbarhet. - **Bevegelse**: Fysisk aktivitet (spesielt ute) forbedrer konsentrasjon og hukommelse. - **Sjekk søvn og kosthold**: Er hun trøtt? Får hun nok jern, omega-3 og proteiner? (Mangel kan påvirke hjernen.) - **Legg merke til styrker**: Kanskje hun husker detaljer fra en film eller en samtale forrige uke? Barns hukommelse er ofte **selektiv** – de husker det som interesserer dem. --- ### **Hvorfor blir du så frustrert?** Det er **helt naturlig** å føle irritasjon når du opplever at du må gjenta deg selv eller bekymre deg for sikkerheten til noen du er glad i. Frustrasjonen kommer ofte av: - **Maktløshet**: Du føler at du ikke har kontroll, og at du ikke får "gjennomslag" for det du sier. - **Utmattelse**: Å være "sandwich-generasjonen" (mellom barn og eldre) er slitsomt. Du har kanskje ikke tid til å ta vare på deg selv. - **Skyldfølelse**: Du vet at de ikke gjør det med vilje, men likevel reagerer du følelsesmessig. **Hva kan du gjøre for deg selv?** - **Sett grenser**: Det er ok å si "Jeg blir sliten av å måtte minne deg på dette hele tiden" – uten å klandre. - **Be om hjelp**: Kan andre i familien ta en del av ansvaret? Eller kan dere få avlastningstjenester fra kommunen? - **Pustepauser**: Når frustrasjonen bygger seg opp, prøv å ta **tre dype pust** før du reagerer. Si til deg selv: *"Dette er ikke deres skyld. De trenger meg."* - **Søk støtte**: Snakk med andre i samme situasjon (f.eks. i foreldregrupper eller demensforeningen). Du er ikke alene. --- ### **Når bør du søke hjelp?** - **For bestemor**: Hvis hun viser andre tegn på demens (f.eks. gjentar de samme spørsmålene, glemmer navn på nære familiemedlemmer, eller har endret personlighet), bør fastlegen vurdere en **kognitiv test**. - **For datter**: Hvis hun sliter med å følge med på skolen, har store humørsvingninger eller virker uvanlig glemsom sammenlignet med jevnaldrende, kan en **pedagogisk-psykologisk tjeneste (PPT)** eller barnelege hjelpe. --- ### **Siste tanke** Både barn og eldre er i faser av livet der hjernen er i **stor endring** – men på helt forskjellige måter. Det er ikke deres "feil" at de glemmer, men det er **din utfordring** å tilpasse deg deres behov. Det er utrolig verdifullt det du gjør, selv om det føles tungt noen ganger. **Du fortjener også omsorg.** Hvis du vil, kan du fortelle mer om situasjonen – da kan jeg kanskje gi mer konkrete råd. 💙 | E104: Ikke mulig å avgjøre | G104: bestemor | I104: min datter | J104: Hvis teksten passer ikke tydelig med ans0, ans1 eller ans2, eller inneholder en TYDELIG kombinasjon av ans0, ans1 og ans2, så gjerne fyll feltet med FLAGG.
B105: Det høres ut som både din bestemor og datter har utfordringer med ulike aspekter av hukommelse og oppmerksomhet, men av helt forskjellige årsaker. Her er en mulig forklaring på hva som kan ligge bak, og hvem som sannsynligvis har en "grei" hukommelse i tradisjonell forstand: ### **Din bestemor (eldre voksen):** - **Hva som skjer:** At hun er ute til alle døgnets tider og ikke alltid husker hvor hun har vært, kan skyldes flere ting: - **Aldersrelaterte endringer i hukommelse** (f.eks. mild kognitiv svikt eller tidlige tegn på demens, som påvirker episodisk hukommelse – evnen til å huske nylige hendelser). - **Redusert orienteringsevne** (kan bli forvirret på tid/sted, spesielt i ukjente omgivelser). - **Sosiale eller psykologiske årsaker** (f.eks. ensomhet, angst eller et ønske om å opprettholde uavhengighet, som gjør at hun "glemmer" å si fra). - **Søvnproblemer** (eldre kan ha forstyrret døgnrytme, noe som påvirker hukommelsen). - **Har hun "grei hukommelse"?** - **Ja, sannsynligvis på noen områder.** Mange eldre har god **langtidshukommelse** (husker gamle minner, ferdigheter, språk) og **prosedural hukommelse** (f.eks. å sykle eller lage mat), men sliter med **korttidshukommelse** og **arbeidshukommelse** (å huske hva som skjedde for 10 minutter siden). - Hvis hun ellers fungerer godt i dagliglivet (husker navn, samtaler, rutiner), kan det være snakk om **normal aldring** – men det er viktig å utelukke andre årsaker (f.eks. depresjon, vitaminmangel, medisinbivirkninger). --- ### **Din datter (barn/ungdom):** - **Hva som skjer:** At hun ikke husker det dere snakket om for fem minutter siden, kan tyde på: - **Umoden arbeidshukommelse** (hjernen er fortsatt under utvikling, spesielt hos barn/ungdom. Arbeidshukommelsen – evnen til å holde og bearbeide informasjon midlertidig – modnes først i 20-årene). - **ADHD eller oppmerksomhetsvansker** (hvis hun også er lett distrahert, glemmer skoleoppgaver eller har kaotiske rutiner, kan dette være en faktor). - **Overbelastning** (barn/ungdom blir lett overveldet av for mye informasjon på en gang). - **Manglende interesse/motivasjon** (hukommelsen fungerer bedre når noe er relevant eller engasjerende). - **Har hun "grei hukommelse"?** - **Ja, men på andre måter enn voksne.** Barn har ofte **god episodisk hukommelse** (husker hendelser de bryr seg om, f.eks. bursdager eller ferier), men sliter med å huske **abstrakte eller kjedelige detaljer** (f.eks. "Hva sa mamma at jeg skulle kjøpe i butikken?"). - Hvis hun husker ting **når hun får påminnelser eller skriver det ned**, er det sannsynligvis **normal utvikling** (eller mild oppmerksomhetsvanske). Hvis hun også sliter med skole, organisering eller impulsivitet, kan det være lurt å snakke med helsesøster/lege om ADHD. --- ### **Hvem har sannsynligvis "grei" hukommelse?** - **Din datter** har sannsynligvis en **funksjonell hukommelse for sin alder**, men den er **selektiv og situasjonsavhengig**. Hun husker det som er viktig for henne, men trenger hjelp til å strukturere informasjon (f.eks. lister, påminnelser, repetisjon). - **Din bestemor** kan ha **god langtidshukommelse**, men **svekket korttidshukommelse** – noe som er vanlig med alderen. Hvis hun ellers klarer seg bra, er det sannsynligvis ikke noe alvorlig, men det kan være lurt å sjekke om hun har **demenstegn** (f.eks. gjentar de samme spørsmålene, glemmer nylige samtaler, eller viser tegn til forvirring). --- ### **Hva kan du gjøre?** #### **For din bestemor:** 1. **Sikkerhet først:** - Gi henne en **GPS-sporingsenhet** (f.eks. klokke eller nøkkelbrikke) hvis hun ofte går seg bort. - Sørg for at hun har **navn og telefonnummer** i lomma/lommeboka. - Snakk med naboer/venner om å holde et ekstra øye med henne. 2. **Rutiner og påminnelser:** - Skriv opp **daglige planer** på et synlig sted (f.eks. tavle på kjøleskapet). - Bruk **alarmer** på telefonen hennes for viktige aktiviteter (f.eks. "Husk å ta medisiner kl. 12"). 3. **Sosial kontakt:** - Eldre som vandrer kan gjøre det av **ensomhet eller rastløshet**. Prøv å involvere henne i aktiviteter (f.eks. daglig senter, besøk fra familie). 4. **Legeundersøkelse:** - Be fastlegen sjekke om det kan være **demens, depresjon, eller bivirkninger av medisiner**. #### **For din datter:** 1. **Gjør informasjon "sticky":** - **Visuell hjelp:** Skriv ned beskjeder på post-it-lapper eller i en felles kalender (f.eks. Google Calendar). - **Repetisjon:** Be henne **gjenta** det dere snakket om ("Hva var det jeg sa at du skulle huske?"). - **Koble til følelser/interesser:** Hvis hun liker dyr, kan du f.eks. si: "Husk å mate katten – den blir sulten som en løve hvis du glemmer!" 2. **Del opp oppgaver:** - I stedet for "Rydd rommet ditt", si: "Først tar du opp klærne fra gulvet, så legger du bøkene på hylla." 3. **Sjekk for ADHD:** - Hvis hun også sliter med **konsentrasjon, organisering eller impulsivitet**, kan det være lurt å ta en samtale med helsesøster/lege. 4. **Ros når hun husker:** - Positiv forsterkning fungerer bedre enn kritikk. Si f.eks.: "Så flott at du husket å ta med gymtøyet i dag!" --- ### **Oppsummering:** - **Din datter** har sannsynligvis en **normal, men umoden hukommelse** for sin alder. Hun trenger **struktur og påminnelser**. - **Din bestemor** har sannsynligvis **aldersrelaterte hukommelsesendringer**, men hvis det er **plutselige eller alvorlige** forandringer, bør hun undersøkes. - **Du gjør en god jobb** ved å være oppmerksom på dette – frustrasjon er forståelig, men både barn og eldre trenger **tålmodighet og tilrettelegging**. Hvis du lurer på om noe av dette kan være **unormalt** (f.eks. demens hos bestemor eller ADHD hos datter), er det alltid lurt å ta en prat med fastlegen. 😊 | E105: min datter | G105: Ikke mulig å avgjøre | I105: bestemor | J105: Hvis teksten passer ikke tydelig med ans0, ans1 eller ans2, eller inneholder en TYDELIG kombinasjon av ans0, ans1 og ans2, så gjerne fyll feltet med FLAGG.
